Workbook

Sheet Sheet0
A2: 지사 | B2: 상품 | C2: 업체명 | D2: 사업자번호 | E2: 등록자 | F2: 활동일 | G2: 방문장소 (시, 군, 구까지) | H2: 활동구분 | I2: 활동상세 | J2: 업무번호 (플로우에 식권, 비즈플레이, 플로우 작성번호) | K2: 제목 | L2: 활동내용

Sheet Sheet1
B3: 활동구분 | C3: 활동상세
B4: 방문A | C4: 부가상품제안
B5: 방문B | C5: 마케팅
B6: 상담 | C6: 개설
B7: 원격 | C7: 연계
C8: 운영

Sheet Sheet2
B2: 사업자번호 | C2: 주소1
B3: 580104 | C3: 경기도 부천시 소사구 송내2동
B4: 1208687945 | C4: 경기도 안성시 죽산면 장계길
B5: 1278159805 | C5: 경기도 동두천시 삼육사로596번길
B6: 1208781443 | C6: 서울시 광진구 광나루로 56길 85
B7: 1228105605 | C7: 경기도 파주시 동패동
B8: 1048120501 | C8: 서울특별시 서초구 서초대로
B9: 1298684571 | C9: 서울특별시 금천구 두산로
B10: 1048617068 | C10: 서울특별시 서대문구 충정로
B11: 1208185957 | C11: 서울특별시 용산구 한강대로21나길
B12: 1308117927 | C12: 경기도 부천시 원미구 부천로198번길
B13: 1228153413 | C13: 인천광역시 부평구 부평대로
... B191: 2108208677 | C191: 서울특별시 노원구 광운로 20길
B192: 1058111908
B193: 1208754460 | C193: 서울특별시 강남구 영동대로
B194: 2208607635 | C194: 서울특별시 강남구 테헤란로
B195: 2158172901 | C195: 경기도 성남시분당구 판교역로 220
B196: 1268652672 | C196: 경기도 하남시 덕풍로
B197: 1068212299 | C197: 경기도 용인시 수지구 죽전로
B198: 1138639969 | C198: 서울 구로구 구로동
B199: 1358192479 | C199: 서울시 세종로 9길 41 퍼시픽타워 14층
B200: 1048191189 | C200: 서울시 중구 세종대로
B201: 1168134177 | C201: 서울시 영등포구 국제금융로 24
B202: 1248132942 | C202: 경기도 오산시 남부대로
B203: 1128131178 | C203: 서울특별시 서초구 반포대로
B204: 1208612537 | C204: 경기도 성남시 분당구 서현로
... B735: 1088143409 | C735: 경기도 성남시 분당구 안양판교로828번길
B736: 1238109055
B737: 3058213385 | C737: 대전광역시 동구 대학로
B738: 3068202732 | C738: 대전광역시 동구 대학로
B739: 1138106798 | C739: 서울특별시 마포구 양화로
B740: 6098129083 | C740: 서울특별시 마포구 양화로
B741: 1208144752 | C741: 서울특별시 강남구 테헤란로
B742: 1168132242 | C742: 전라남도 나주시 빛가람로
B743: 2118208632 | C743: 서울시 강서구
B744: 4038200258 | C744: 전라북도 익산시 익산대로
B745: 2148600845 | C745: 서울 중구 을지로2가
B746: 4068163838 | C746: 서울특별시 강남구 영동대로96길
B747: 1388202371 | C747: 서울특별시 중구 남대문로
B748: 2128105946 | C748: 서울특별시 강동구 상일로10길
...

Sheet Sheet3
B2: 성명 | C2: 구분 | D2: CNT
B3: 이성환 | C3: 개설 | D3: =COUNTIFS(Sheet0!E:E,Sheet3!B3:B20,Sheet0!I:I,Sheet3!C3:C20) -> 0
B4: 임인지 | C4: 개설 | D4: =COUNTIFS(Sheet0!E:E,Sheet3!B4:B21,Sheet0!I:I,Sheet3!C4:C21) -> 0
B5: 전준수 | C5: 개설 | D5: =COUNTIFS(Sheet0!E:E,Sheet3!B5:B22,Sheet0!I:I,Sheet3!C5:C22) -> 0 | H5: 이성환 | I5: 임인지 | J5: 전준수 | K5: 이수현 | L5: 하성춘 | M5: 길민종
B6: 이수현 | C6: 개설 | D6: =COUNTIFS(Sheet0!E:E,Sheet3!B6:B23,Sheet0!I:I,Sheet3!C6:C23) -> 0 | F6: 개설 | G6: 90 | H6: =G6*D3 -> 0 | I6: =G6*D4 -> 0 | J6: =G6*D5 -> 0 | K6: =G6*D6 -> 0 | L6: =G6*D7 -> 0 | M6: =G6*D8 -> 0
B7: 하성춘 | C7: 개설 | D7: =COUNTIFS(Sheet0!E:E,Sheet3!B7:B24,Sheet0!I:I,Sheet3!C7:C24) -> 0 | F7: 연계 | G7: 120 | H7: =G7*D9 -> 0 | I7: =G7*D10 -> 0 | J7: =G7*D11 -> 0 | K7: =G7*D12 -> 0 | L7: =G7*D13 -> 0 | M7: =G7*D14 -> 0
B8: 길민종 | C8: 개설 | D8: =COUNTIFS(Sheet0!E:E,Sheet3!B8:B25,Sheet0!I:I,Sheet3!C8:C25) -> 0 | H8: =H6+H7 -> 0 | I8: =I6+I7 -> 0 | J8: =J6+J7 -> 0 | K8: =K6+K7 -> 0 | L8: =L6+L7 -> 0 | M8: =M6+M7 -> 0
B9: 이성환 | C9: 연계 | D9: =COUNTIFS(Sheet0!E:E,Sheet3!B9:B26,Sheet0!I:I,Sheet3!C9:C26) -> 0
B10: 임인지 | C10: 연계 | D10: =COUNTIFS(Sheet0!E:E,Sheet3!B10:B27,Sheet0!I:I,Sheet3!C10:C27) -> 0
B11: 전준수 | C11: 연계 | D11: =COUNTIFS(Sheet0!E:E,Sheet3!B11:B28,Sheet0!I:I,Sheet3!C11:C28) -> 0
B12: 이수현 | C12: 연계 | D12: =COUNTIFS(Sheet0!E:E,Sheet3!B12:B29,Sheet0!I:I,Sheet3!C12:C29) -> 0
B13: 하성춘 | C13: 연계 | D13: =COUNTIFS(Sheet0!E:E,Sheet3!B13:B30,Sheet0!I:I,Sheet3!C13:C30) -> 0
B14: 길민종 | C14: 연계 | D14: =COUNTIFS(Sheet0!E:E,Sheet3!B14:B31,Sheet0!I:I,Sheet3!C14:C31) -> 0
B15: 이성환 | C15: 운영 | D15: =COUNTIFS(Sheet0!E:E,Sheet3!B15:B32,Sheet0!I:I,Sheet3!C15:C32) -> 0
B16: 임인지 | C16: 운영 | D16: =COUNTIFS(Sheet0!E:E,Sheet3!B16:B33,Sheet0!I:I,Sheet3!C16:C33) -> 0
B17: 전준수 | C17: 운영 | D17: =COUNTIFS(Sheet0!E:E,Sheet3!B17:B34,Sheet0!I:I,Sheet3!C17:C34) -> 0
B18: 이수현 | C18: 운영 | D18: =COUNTIFS(Sheet0!E:E,Sheet3!B18:B35,Sheet0!I:I,Sheet3!C18:C35) -> 0
B19: 하성춘 | C19: 운영 | D19: =COUNTIFS(Sheet0!E:E,Sheet3!B19:B36,Sheet0!I:I,Sheet3!C19:C36) -> 0
B20: 길민종 | C20: 운영 | D20: =COUNTIFS(Sheet0!E:E,Sheet3!B20:B37,Sheet0!I:I,Sheet3!C20:C37) -> 0
